Workbook

Sheet Sources
A1: Tech Pulse: candidate sources
A2: How to use: in the yellow 'Include?' column, choose Yes or No for each source. Add your own sources at the bottom (any site with an RSS feed, or any YouTube channel). Every feed was tested on 28 Oct 2026.
A4: Include? | B4: Section | C4: Source | D4: Type | E4: What it covers | F4: Feed works? | G4: Latest post | H4: Posts in last 7 days | I4: Feed URL
A5: Yes | B5: Big Tech & Labs | C5: Google | D5: Official company blog | E5: Google's own announcements (The Keyword) | F5: Yes | G5: 46322 | H5: 14 | I5: https://blog.google/rss/
A6: Yes | B6: Big Tech & Labs | C6: Microsoft | D6: Official company blog | E6: Microsoft corporate announcements | F6: Yes | G6: 46322 | H6: 2 | I6: https://blogs.microsoft.com/feed/
A7: Yes | B7: Big Tech & Labs | C7: Apple Newsroom | D7: Official company blog | E7: Apple press releases | F7: Yes | G7: 46322 | H7: 8 | I7: https://www.apple.com/newsroom/rss-feed.rss
A8: Yes | B8: Big Tech & Labs | C8: AWS News | D8: Official company blog | E8: New AWS services and launches | F8: Yes | G8: 46321 | H8: 2 | I8: https://aws.amazon.com/blogs/aws/feed/
A9: Yes | B9: Big Tech & Labs | C9: NVIDIA | D9: Official company blog | E9: GPUs, AI computing, data centres | F9: Yes | G9: 46322 | H9: 18 | I9: https://blogs.nvidia.com/feed/
A10: Yes | B10: Big Tech & Labs | C10: OpenAI | D10: Official company blog | E10: OpenAI model releases, research, product news | F10: Yes | G10: 46322 | H10: 23 | I10: https://openai.com/news/rss.xml
A11: Yes | B11: Big Tech & Labs | C11: Anthropic | D11: Official company site (scraped, no feed) | E11: Anthropic announcements: Claude models, products, policy | F11: Yes | G11: 46322 | H11: 4 | I11: https://www.anthropic.com/news
A12: Yes | B12: Big Tech & Labs | C12: Google DeepMind | D12: Official company blog | E12: DeepMind research and model releases | F12: Yes | G12: 46322 | H12: 2 | I12: https://deepmind.google/blog/rss.xml
A13: Yes | B13: Big Tech & Labs | C13: Samsung Newsroom | D13: Official company blog | E13: Samsung devices, chips, press releases | F13: Yes | G13: 46322 | H13: 6 | I13: https://news.samsung.com/global/feed
A14: Yes | B14: Big Tech & Labs | C14: Thoughtworks | D14: Official company blog | E14: Thoughtworks insights: AI in delivery, architecture, tech strategy | F14: Yes | G14: 46321 | H14: 4 | I14: https://www.thoughtworks.com/rss/insights.xml
A15: Yes | B15: Model Watch | C15: Hugging Face | D15: Official company blog | E15: Open models, datasets, tooling tutorials | F15: Yes | G15: 46322 | H15: 9 | I15: https://huggingface.co/blog/feed.xml
A16: Yes | B16: Model Watch | C16: Qwen | D16: Official lab blog | E16: Alibaba's Qwen model releases | F16: Yes | G16: 45922 | H16: 0 | I16: https://qwenlm.github.io/blog/index.xml
... A28: Yes | B28: AI & Agents | C28: MarkTechPost | D28: News site | E28: AI research news and paper summaries | F28: Yes | G28: 46322 | H28: 10 | I28: https://www.marktechpost.com/feed/
A29: No | B29: AI & Agents | C29: VentureBeat AI | D29: News site | E29: Enterprise AI business news | F29: No: feed is broken | I29: https://venturebeat.com/category/ai/feed/
A30: Yes | B30: Software Engineering | C30: InfoQ | D30: News site | E30: Software architecture, DevOps, practices, conference talks | F30: Yes | G30: 46322 | H30: 15 | I30: https://feed.infoq.com/
A31: Yes | B31: Software Engineering | C31: Martin Fowler | D31: Expert blog | E31: Software design, refactoring, architecture | F31: Yes | G31: 46316 | H31: 1 | I31: https://martinfowler.com/feed.atom
A32: Yes | B32: Software Engineering | C32: The Pragmatic Engineer | D32: Newsletter | E32: Gergely Orosz on the software industry and teams | F32: Yes | G32: 46322 | H32: 3 | I32: https://newsletter.pragmaticengineer.com/feed
A33: Yes | B33: Software Engineering | C33: GitHub Blog | D33: Official company blog | E33: GitHub, Copilot, open source, dev tooling | F33: Yes | G33: 46317 | H33: 2 | I33: https://github.blog/feed/
A34: Yes | B34: Software Engineering | C34: Stack Overflow Blog | D34: Official company blog | E34: Developer trends, surveys, engineering | F34: Yes | G34: 46322 | H34: 5 | I34: https://stackoverflow.blog/feed/
A35: Yes | B35: Software Engineering | C35: IEEE Spectrum Computing | D35: Magazine | E35: IEEE coverage of computing and software | F35: Yes | G35: 46320 | H35: 3 | I35: https://spectrum.ieee.org/feeds/topic/computing.rss
A36: Yes | B36: Software Engineering | C36: LWN.net | D36: News site | E36: Linux kernel and open-source development | F36: Yes | G36: 46322 | H36: 15 | I36: https://lwn.net/headlines/rss
A37: No | B37: Software Engineering | C37: Google for Developers | D37: Official company blog | E37: Gemini API, Android, Chrome and Google developer tools | F37: No: feed is broken | I37: https://developers.googleblog.com/feeds/posts/default
A38: Yes | B38: Engineering Blogs | C38: Netflix Tech Blog | D38: Official company blog | E38: Large-scale engineering at Netflix | F38: Yes | G38: 46321 | H38: 4 | I38: https://netflixtechblog.com/feed
A39: Yes | B39: Engineering Blogs | C39: Meta Engineering | D39: Official company blog | E39: Meta engineering: infra, AI, open source | F39: Yes | G39: 46322 | H39: 3 | I39: https://engineering.fb.com/feed/
A40: Yes | B40: Engineering Blogs | C40: Cloudflare | D40: Official company blog | E40: Networking, security, edge computing, AI infra | F40: Yes | G40: 46322 | H40: 9 | I40: https://blog.cloudflare.com/rss/
A41: Yes | B41: Engineering Blogs | C41: Airbnb Engineering | D41: Engineering blog | E41: Search, ML and infrastructure at Airbnb | F41: Yes | G41: 46308 | H41: 0 | I41: https://medium.com/feed/airbnb-engineering
A42: Yes | B42: Engineering Blogs | C42: Spotify Engineering | D42: Engineering blog | E42: Recommendation systems and platform engineering at Spotify | F42: Yes | G42: 46311 | H42: 0 | I42: https://engineering.atspotify.com/feed/
A43: Yes | B43: Engineering Blogs | C43: Stripe | D43: Official company blog | E43: Payments infrastructure and Stripe engineering | F43: Yes | G43: 46322 | H43: 2 | I43: https://stripe.com/blog/feed.rss
A44: Yes | B44: Engineering Blogs | C44: Slack Engineering | D44: Engineering blog | E44: Slack's infrastructure and developer tooling | F44: Yes | G44: 46217 | H44: 0 | I44: https://slack.engineering/feed/
A45: Yes | B45: Engineering Blogs | C45: Dropbox Tech | D45: Engineering blog | E45: Storage, infrastructure and AI at Dropbox | F45: Yes | G45: 46294 | H45: 0 | I45: https://dropbox.tech/feed
A46: Yes | B46: Engineering Blogs | C46: Pinterest Engineering | D46: Engineering blog | E46: ML, data and infrastructure at Pinterest | F46: Yes | G46: 46314 | H46: 0 | I46: https://medium.com/feed/@Pinterest_Engineering
A47: Yes | B47: Engineering Blogs | C47: Shopify Engineering | D47: Engineering blog | E47: Commerce platform engineering at Shopify | F47: Yes | G47: 46317 | H47: 1 | I47: https://shopify.engineering/blog.atom
A48: Yes | B48: Engineering Blogs | C48: Lyft Engineering | D48: Engineering blog | E48: Marketplace, mapping and data engineering at Lyft | F48: Yes | G48: 46275 | H48: 0 | I48: https://eng.lyft.com/feed
A49: Yes | B49: Engineering Blogs | C49: Datadog Engineering | D49: Engineering blog | E49: Observability, distributed systems and security at Datadog | F49: Yes | G49: 46315 | H49: 0 | I49: https://www.datadoghq.com/blog/engineering/index.xml
... A81: Yes | B81: Tech News | C81: 9to5Google | D81: News site | E81: Google, Android, Pixel (high volume) | F81: Yes | G81: 46322 | H81: 25 | I81: https://9to5google.com/feed/
A82: Yes | B82: Videos | C82: MKBHD | D82: YouTube channel | E82: Phone and gadget reviews | F82: Not checked: YouTube feeds were down during this check | I82: https://www.youtube.com/feeds/videos.xml?channel_id=UCBJycsmduvYEL83R_U4JriQ
A83: Yes | B83: Videos | C83: Linus Tech Tips | D83: YouTube channel | E83: PC hardware, gadgets | F83: Not checked: YouTube feeds were down during this check | I83: https://www.youtube.com/feeds/videos.xml?channel_id=UCXuqSBlHAE6Xw-yeJA0Tunw
...

Sheet Paper venues
A1: Tech Pulse: research paper sources
A2: Conferences: papers whose authors note on arXiv that they were accepted there (this year and next). Journals: newest 60 articles with abstracts (OpenAlex). Topics: newest arXiv papers matching a search. Counts are from 28 Oct 2026. Set Include? to Yes or No; add venues in the blank rows.
A4: Include? | B4: Kind | C4: Field | D4: Venue | E4: Full name / search | F4: Papers found now | G4: Where the papers come from
A5: Yes | B5: Conference | C5: Software Engineering | D5: ICSE | E5: International Conference on Software Engineering | F5: 2027: 8, 2026: 130 | G5: arXiv author notes + official program link
A6: Yes | B6: Conference | C6: Software Engineering | D6: FSE | E6: Foundations of Software Engineering | F6: 2026: 85 | G6: arXiv author notes + official program link
A7: Yes | B7: Conference | C7: Software Engineering | D7: ASE | E7: Automated Software Engineering | F7: 2026: 97 | G7: arXiv author notes + official program link
A8: Yes | B8: Conference | C8: Software Engineering | D8: ISSTA | E8: Software Testing and Analysis | F8: 2026: 52 | G8: arXiv author notes + official program link
A9: Yes | B9: Conference | C9: Software Engineering | D9: MSR | E9: Mining Software Repositories | F9: 2026: 32 | G9: arXiv author notes + official program link
A10: Yes | B10: Conference | C10: Software Engineering | D10: ICSME | E10: Software Maintenance and Evolution | F10: 2026: 35 | G10: arXiv author notes + official program link
A11: Yes | B11: Conference | C11: Software Engineering | D11: SANER | E11: Software Analysis, Evolution and Reengineering | F11: 2026: 18 | G11: arXiv author notes + official program link
A12: Yes | B12: Conference | C12: Software Engineering | D12: ESEM | E12: Empirical Software Engineering and Measurement | F12: 2026: 22 | G12: arXiv author notes + official program link
A13: Yes | B13: Conference | C13: Software Engineering | D13: ICSA | E13: Software Architecture | F13: 2026: 14 | G13: arXiv author notes + official program link
A14: Yes | B14: Conference | C14: Software Engineering | D14: RE | E14: Requirements Engineering | F14: 2026: 7 | G14: arXiv author notes + official program link
A15: Yes | B15: Conference | C15: Software Engineering | D15: EASE | E15: Evaluation and Assessment in Software Engineering | F15: 2026: 43 | G15: arXiv author notes + official program link
... A26: Yes | B26: Conference | C26: Sustainability & Energy | D26: e-Energy | E26: ACM Future Energy Systems | F26: 2026: 7 | G26: arXiv author notes + official program link
A27: Yes | B27: Journal | C27: Software Engineering | D27: TSE | E27: IEEE Transactions on Software Engineering | F27: 60 | G27: OpenAlex, ISSN 0098-5589
A28: Yes | B28: Journal | C28: Software Engineering | D28: TOSEM | E28: ACM Transactions on Software Engineering and Methodology | F28: 60 | G28: OpenAlex, ISSN 1049-331X
A29: Yes | B29: Journal | C29: Software Engineering | D29: PACMSE | E29: Proc. ACM on Software Engineering (FSE, ISSTA papers) | F29: 60 | G29: OpenAlex, ISSN 2994-970X
A30: Yes | B30: Journal | C30: Software Engineering | D30: EMSE | E30: Empirical Software Engineering | F30: 60 | G30: OpenAlex, ISSN 1382-3256
A31: Yes | B31: Journal | C31: Software Engineering | D31: JSS | E31: Journal of Systems and Software | F31: 60 | G31: OpenAlex, ISSN 0164-1212
A32: Yes | B32: Journal | C32: Software Engineering | D32: IST | E32: Information and Software Technology | F32: 60 | G32: OpenAlex, ISSN 0950-5849
A33: Yes | B33: Journal | C33: Software Engineering | D33: IEEE Software | E33: IEEE Software | F33: 60 | G33: OpenAlex, ISSN 0740-7459
A34: Yes | B34: Journal | C34: Software Engineering | D34: ASEJ | E34: Automated Software Engineering (journal) | F34: 60 | G34: OpenAlex, ISSN 0928-8910
A35: Yes | B35: Journal | C35: AI, ML & Agents | D35: JAIR | E35: Journal of Artificial Intelligence Research | F35: 60 | G35: OpenAlex, ISSN 1076-9757
A36: Yes | B36: Journal | C36: AI, ML & Agents | D36: JMLR | E36: Journal of Machine Learning Research | F36: 60 | G36: OpenAlex, ISSN 1532-4435
A37: Yes | B37: Journal | C37: AI, ML & Agents | D37: Nat. Mach. Intell. | E37: Nature Machine Intelligence | F37: 60 | G37: OpenAlex, ISSN 2522-5839
A38: Yes | B38: Journal | C38: Sustainability & Energy | D38: SUSCOM | E38: Sustainable Computing: Informatics and Systems | F38: 60 | G38: OpenAlex, ISSN 2210-5379
A39: Yes | B39: Topic search | D39: LLM agents & agentic AI | E39: abs:"agentic" OR abs:"LLM agent" OR abs:"LLM-based agent" OR abs:"multi-agent system" | F39: 60 in last 10 days | G39: arXiv search
A40: Yes | B40: Topic search | D40: AI for software engineering | E40: cat:cs.SE AND (abs:LLM OR abs:"large language model" OR abs:agent) | F40: 60 in last 10 days | G40: arXiv search
A41: Yes | B41: Topic search | D41: Green AI & energy | E41: (abs:"energy consumption" OR abs:"energy efficiency" OR abs:"carbon footprint" OR abs:"green software") AND (abs:LLM OR abs:"language model" OR abs:software) | F41: 16 in last 10 days | G41: arXiv search
A42: Yes | B42: Topic search | D42: Uncertainty in LLMs & agents | E42: abs:uncertainty AND (abs:LLM OR abs:agent) | F42: 50 in last 10 days | G42: arXiv search
A43: Yes | B43: Topic search | D43: Every new cs.SE paper | E43: cat:cs.SE | F43: 60 in last 10 days | G43: arXiv search
D44: (add your own here)

Sheet Summary
A1: What you've chosen
A2: Updates automatically as you change Yes/No on the Sources sheet.
A4: Section | B4: Sources available | C4: Sources chosen
A5: Big Tech & Labs | B5: =COUNTIF(Sources!$B$5:$B$110,A5) | C5: =COUNTIFS(Sources!$B$5:$B$110,A5,Sources!$A$5:$A$110,"Yes")
A6: Model Watch | B6: =COUNTIF(Sources!$B$5:$B$110,A6) | C6: =COUNTIFS(Sources!$B$5:$B$110,A6,Sources!$A$5:$A$110,"Yes")
A7: AI & Agents | B7: =COUNTIF(Sources!$B$5:$B$110,A7) | C7: =COUNTIFS(Sources!$B$5:$B$110,A7,Sources!$A$5:$A$110,"Yes")
A8: Software Engineering | B8: =COUNTIF(Sources!$B$5:$B$110,A8) | C8: =COUNTIFS(Sources!$B$5:$B$110,A8,Sources!$A$5:$A$110,"Yes")
A9: Engineering Blogs | B9: =COUNTIF(Sources!$B$5:$B$110,A9) | C9: =COUNTIFS(Sources!$B$5:$B$110,A9,Sources!$A$5:$A$110,"Yes")
A10: Sustainability & Energy | B10: =COUNTIF(Sources!$B$5:$B$110,A10) | C10: =COUNTIFS(Sources!$B$5:$B$110,A10,Sources!$A$5:$A$110,"Yes")
A11: Security | B11: =COUNTIF(Sources!$B$5:$B$110,A11) | C11: =COUNTIFS(Sources!$B$5:$B$110,A11,Sources!$A$5:$A$110,"Yes")
A12: Hardware & Chips | B12: =COUNTIF(Sources!$B$5:$B$110,A12) | C12: =COUNTIFS(Sources!$B$5:$B$110,A12,Sources!$A$5:$A$110,"Yes")
A13: Tech News | B13: =COUNTIF(Sources!$B$5:$B$110,A13) | C13: =COUNTIFS(Sources!$B$5:$B$110,A13,Sources!$A$5:$A$110,"Yes")
A14: Videos | B14: =COUNTIF(Sources!$B$5:$B$110,A14) | C14: =COUNTIFS(Sources!$B$5:$B$110,A14,Sources!$A$5:$A$110,"Yes")
A15: Total | B15: =SUM(B5:B14) | C15: =SUM(C5:C14)
A18: Notes
A19: Anthropic, Meta AI (ai.meta.com) and The Batch (DeepLearning.AI) publish no RSS feed, so they can't be followed automatically. Their stories still show up through Techmeme, The Verge, The Decoder and others.
A20: arXiv searches are tuned to your research (agents, AI for SE, LLM energy, uncertainty). Tell me other keywords and I'll add them.
A21: Any YouTube channel can be added: give me the channel link.
A22: The site updates itself every hour: new posts from every chosen source appear on their own.
